Workbook
Name Slicer_Employment_Status: #N/A
Name Slicer_Major: #N/A

Sheet Read Me
A1: Student Career Outcomes & Engagement Dashboard Dataset
A3: Purpose | B3: Synthetic dataset built to demonstrate Excel data organization, INDEX/MATCH lookups, summary analysis, and dashboard-ready reporting.
A4: Sheets | B4: Students, Engagement, Outcomes are source sheets. Master_Data combines them using INDEX/MATCH. Summary_Analysis powers the Dashboard.
A5: How to use | B5: Open Master_Data to review formulas. Open Dashboard to see KPI cards and charts. Edit source sheets to test formula updates.
A6: Rows | B6: 120 synthetic student records
A7: Key skills shown | B7: Excel formulas, INDEX/MATCH, COUNTIFS, AVERAGEIFS, IF logic, structured workbook design, charting

Sheet Students
A1: Student_ID | B1: Student_Name | C1: Major | D1: Degree_Level | E1: Graduation_Year | F1: GPA | G1: International_Status
A2: S001 | B2: Morgan Smith | C2: Finance | D2: Undergraduate | E2: 2026 | F2: 2.92 | G2: No
A3: S002 | B3: Rowan Brown | C3: Data Science | D3: Undergraduate | E3: 2026 | F3: 3.08 | G3: No
A4: S003 | B4: Rowan Miller | C4: Data Science | D4: Graduate | E4: 2026 | F4: 3.34 | G4: Yes
A5: S004 | B5: Alex Garcia | C5: Data Science | D5: Undergraduate | E5: 2026 | F5: 3.95 | G5: Yes
A6: S005 | B6: Taylor Martin | C6: Business Analytics | D6: Graduate | E6: 2026 | F6: 3.77 | G6: No
A7: S006 | B7: Rowan Lee | C7: Marketing | D7: Undergraduate | E7: 2026 | F7: 3.8 | G7: No
A8: S007 | B8: Parker Walker | C8: Business Analytics | D8: Undergraduate | E8: 2027 | F8: 3.73 | G8: No
A9: S008 | B9: Cameron Lee | C9: Computer Science | D9: Graduate | E9: 2027 | F9: 3 | G9: No
A10: S009 | B10: Drew Brown | C10: Data Science | D10: Undergraduate | E10: 2027 | F10: 3 | G10: No
A11: S010 | B11: Rowan Davis | C11: Data Science | D11: Graduate | E11: 2027 | F11: 3.07 | G11: Yes
A12: S011 | B12: Skyler Martin | C12: Computer Science | D12: Undergraduate | E12: 2027 | F12: 3.85 | G12: Yes
A13: S012 | B13: Emerson Martin | C13: Marketing | D13: Graduate | E13: 2026 | F13: 2.97 | G13: No
... A121: S120 | B121: Avery Hall | C121: Economics | D121: Graduate | E121: 2027 | F121: 3.13 | G121: No

Sheet Engagement
A1: Student_ID | B1: Workshops_Attended | C1: Resume_Reviews | D1: Mock_Interviews | E1: Career_Fair_Attendance
A2: S001 | B2: 0 | C2: 2 | D2: 0 | E2: 1
A3: S002 | B3: 1 | C3: 1 | D3: 2 | E3: 0
A4: S003 | B4: 4 | C4: 2 | D4: 1 | E4: 3
A5: S004 | B5: 3 | C5: 1 | D5: 2 | E5: 1
A6: S005 | B6: 2 | C6: 3 | D6: 1 | E6: 3
A7: S006 | B7: 5 | C7: 0 | D7: 0 | E7: 1
A8: S007 | B8: 4 | C8: 1 | D8: 3 | E8: 1
A9: S008 | B9: 3 | C9: 1 | D9: 3 | E9: 3
A10: S009 | B10: 4 | C10: 1 | D10: 1 | E10: 1
A11: S010 | B11: 3 | C11: 1 | D11: 2 | E11: 2
A12: S011 | B12: 3 | C12: 1 | D12: 1 | E12: 1
A13: S012 | B13: 4 | C13: 1 | D13: 0 | E13: 2
... A121: S120 | B121: 4 | C121: 3 | D121: 0 | E121: 1

Sheet Outcomes
A1: Student_ID | B1: Internship_Status | C1: Employment_Status | D1: Employment_Type | E1: Industry | F1: Salary | G1: Months_to_Employment
A2: S001 | B2: Yes | C2: Employed | D2: Part-Time | E2: Finance | F2: 34434 | G2: 2
A3: S002 | B3: No | C3: Seeking | D3: NA | E3: NA
A4: S003 | B4: Yes | C4: Employed | D4: Part-Time | E4: Technology | F4: 42873 | G4: 4
A5: S004 | B5: No | C5: Employed | D5: Full-Time | E5: Education | F5: 53883 | G5: 3
A6: S005 | B6: Yes | C6: Employed | D6: Full-Time | E6: Healthcare | F6: 64304 | G6: 4
A7: S006 | B7: No | C7: Seeking | D7: NA | E7: NA
A8: S007 | B8: No | C8: Seeking | D8: NA | E8: NA
A9: S008 | B9: No | C9: Employed | D9: Full-Time | E9: Marketing | F9: 53353 | G9: 2
A10: S009 | B10: Yes | C10: Employed | D10: Internship | E10: Technology | F10: 37985 | G10: 5
A11: S010 | B11: Yes | C11: Employed | D11: Internship | E11: Technology | F11: 35622 | G11: 5
A12: S011 | B12: Yes | C12: Employed | D12: Full-Time | E12: Marketing | F12: 58812 | G12: 6
A13: S012 | B13: Yes | C13: Seeking | D13: NA | E13: NA
A14: S013 | B14: No | C14: Seeking | D14: NA | E14: NA
A15: S014 | B15: No | C15: Seeking | D15: NA | E15: NA
A16: S015 | B16: Yes | C16: Continuing Education | D16: NA | E16: NA
A17: S016 | B17: Yes | C17: Employed | D17: Full-Time | E17: Technology | F17: 74742 | G17: 1
A18: S017 | B18: Yes | C18: Seeking | D18: NA | E18: NA
A19: S018 | B19: No | C19: Employed | D19: Full-Time | E19: Marketing | F19: 62138 | G19: 4
A20: S019 | B20: Yes | C20: Employed | D20: Full-Time | E20: Consulting | F20: 69158 | G20: 4
A21: S020 | B21: Yes | C21: Employed | D21: Part-Time | E21: Technology | F21: 35830 | G21: 2
A22: S021 | B22: No | C22: Seeking | D22: NA | E22: NA
A23: S022 | B23: Yes | C23: Employed | D23: Full-Time | E23: Technology | F23: 78247 | G23: 1
A24: S023 | B24: Yes | C24: Seeking | D24: NA | E24: NA
A25: S024 | B25: Yes | C25: Seeking | D25: NA | E25: NA
A26: S025 | B26: No | C26: Employed | D26: Full-Time | E26: Finance | F26: 67566 | G26: 1
A27: S026 | B27: Yes | C27: Employed | D27: Part-Time | E27: Technology | F27: 37464 | G27: 2
A28: S027 | B28: Yes | C28: Employed | D28: Full-Time | E28: Finance | F28: 75574 | G28: 1
A29: S028 | B29: Yes | C29: Employed | D29: Internship | E29: Technology | F29: 31898 | G29: 3
A30: S029 | B30: Yes | C30: Employed | D30: Full-Time | E30: Consulting | F30: 69705 | G30: 2
A31: S030 | B31: Yes | C31: Employed | D31: Full-Time | E31: Consulting | F31: 74550 | G31: 2
A32: S031 | B32: Yes | C32: Employed | D32: Internship | E32: Consulting | F32: 37590 | G32: 3
A33: S032 | B33: Yes | C33: Employed | D33: Part-Time | E33: Healthcare | F33: 44598 | G33: 3
A34: S033 | B34: No | C34: Employed | D34: Full-Time | E34: Technology | F34: 75889 | G34: 3
A35: S034 | B35: No | C35: Employed | D35: Full-Time | E35: Healthcare | F35: 60230 | G35: 3
A36: S035 | B36: Yes | C36: Employed | D36: Part-Time | E36: Healthcare | F36: 47866 | G36: 2
A37: S036 | B37: Yes | C37: Seeking | D37: NA | E37: NA
A38: S037 | B38: Yes | C38: Employed | D38: Full-Time | E38: Consulting | F38: 74850 | G38: 1
A39: S038 | B39: Yes | C39: Employed | D39: Full-Time | E39: Retail | F39: 61767 | G39: 3
A40: S039 | B40: Yes | C40: Employed | D40: Full-Time | E40: Technology | F40: 76363 | G40: 4
...

Sheet Master_Data
A1: Student_ID | B1: Student_Name | C1: Major | D1: Degree_Level | E1: Graduation_Year | F1: GPA | G1: International_Status | H1: Workshops_Attended | I1: Resume_Reviews | J1: Mock_Interviews | K1: Career_Fair_Attendance | L1: Internship_Status | M1: Employment_Status | N1: Employment_Type | O1: Industry | P1: Salary | Q1: Months_to_Employment | R1: Total_Engagement | S1: Outcome | T1: Salary Band
A2: S001 | B2: =INDEX(Students!B:B,MATCH(Master_Data!A2,Students!A:A,0)) -> Morgan Smith | C2: =INDEX(Students!C:C,MATCH(Master_Data!A2,Students!A:A,0)) -> Finance | D2: =INDEX(Students!D:D,MATCH(Master_Data!A2,Students!A:A,0)) -> Undergraduate | E2: =INDEX(Students!E:E,MATCH(Master_Data!A2,Students!A:A,0)) -> 2026 | F2: =INDEX(Students!F:F,MATCH(Master_Data!A2,Students!A:A,0)) -> 2.92 | G2: =INDEX(Students!G:G,MATCH(Master_Data!A2,Students!A:A,0)) -> No | H2: =INDEX(Engagement!B:B,MATCH(Master_Data!A2,Engagement!A:A,0)) -> 0 | I2: =INDEX(Engagement!C:C,MATCH(Master_Data!A2,Engagement!A:A,0)) -> 2 | J2: =INDEX(Engagement!D:D,MATCH(Master_Data!A2,Engagement!A:A,0)) -> 0 | K2: =INDEX(Engagement!E:E,MATCH(Master_Data!A2,Engagement!A:A,0)) -> 1 | L2: =INDEX(Outcomes!B:B,MATCH(Master_Data!A2,Engagement!A:A,0)) -> Yes | M2: =INDEX(Outcomes!C:C,MATCH(Master_Data!A2,Engagement!A:A,0)) -> Employed | N2: =INDEX(Outcomes!D:D,MATCH(Master_Data!A2,Engagement!A:A,0)) -> Part-Time | O2: =INDEX(Outcomes!E:E,MATCH(Master_Data!A2,Engagement!A:A,0)) -> Finance | P2: =INDEX(Outcomes!F:F,MATCH(Master_Data!A2,Engagement!A:A,0)) -> 34434 | Q2: =INDEX(Outcomes!G:G,MATCH(Master_Data!A2,Engagement!A:A,0)) -> 2 | R2: =H2+I2+J2+K2 -> 3 | S2: =IF(M2="Employed","Positive Outcome", IF(M2="Continuing Education","Further Study", "Seeking")) -> Positive Outcome | T2: =IF(P2=0,"No Salary", IF(P2<50000,"Below 50K", IF(P2<=75000,"Between 50K and 75K", "Above 75K"))) -> Below 50K
A3: S002 | B3: =INDEX(Students!B:B,MATCH(Master_Data!A3,Students!A:A,0)) -> Rowan Brown | C3: =INDEX(Students!C:C,MATCH(Master_Data!A3,Students!A:A,0)) -> Data Science | D3: =INDEX(Students!D:D,MATCH(Master_Data!A3,Students!A:A,0)) -> Undergraduate | E3: =INDEX(Students!E:E,MATCH(Master_Data!A3,Students!A:A,0)) -> 2026 | F3: =INDEX(Students!F:F,MATCH(Master_Data!A3,Students!A:A,0)) -> 3.08 | G3: =INDEX(Students!G:G,MATCH(Master_Data!A3,Students!A:A,0)) -> No | H3: =INDEX(Engagement!B:B,MATCH(Master_Data!A3,Engagement!A:A,0)) -> 1 | I3: =INDEX(Engagement!C:C,MATCH(Master_Data!A3,Engagement!A:A,0)) -> 1 | J3: =INDEX(Engagement!D:D,MATCH(Master_Data!A3,Engagement!A:A,0)) -> 2 | K3: =INDEX(Engagement!E:E,MATCH(Master_Data!A3,Engagement!A:A,0)) -> 0 | L3: =INDEX(Outcomes!B:B,MATCH(Master_Data!A3,Engagement!A:A,0)) -> No | M3: =INDEX(Outcomes!C:C,MATCH(Master_Data!A3,Engagement!A:A,0)) -> Seeking | N3: =INDEX(Outcomes!D:D,MATCH(Master_Data!A3,Engagement!A:A,0)) -> NA | O3: =INDEX(Outcomes!E:E,MATCH(Master_Data!A3,Engagement!A:A,0)) -> NA | P3: =INDEX(Outcomes!F:F,MATCH(Master_Data!A3,Engagement!A:A,0)) -> 0 | Q3: =INDEX(Outcomes!G:G,MATCH(Master_Data!A3,Engagement!A:A,0)) -> 0 | R3: =H3+I3+J3+K3 -> 4 | S3: =IF(M3="Employed","Positive Outcome", IF(M3="Continuing Education","Further Study", "Seeking")) -> Seeking | T3: =IF(P3=0,"No Salary", IF(P3<50000,"Below 50K", IF(P3<=75000,"Between 50K and 75K", "Above 75K"))) -> No Salary
A4: S003 | B4: =INDEX(Students!B:B,MATCH(Master_Data!A4,Students!A:A,0)) -> Rowan Miller | C4: =INDEX(Students!C:C,MATCH(Master_Data!A4,Students!A:A,0)) -> Data Science | D4: =INDEX(Students!D:D,MATCH(Master_Data!A4,Students!A:A,0)) -> Graduate | E4: =INDEX(Students!E:E,MATCH(Master_Data!A4,Students!A:A,0)) -> 2026 | F4: =INDEX(Students!F:F,MATCH(Master_Data!A4,Students!A:A,0)) -> 3.34 | G4: =INDEX(Students!G:G,MATCH(Master_Data!A4,Students!A:A,0)) -> Yes | H4: =INDEX(Engagement!B:B,MATCH(Master_Data!A4,Engagement!A:A,0)) -> 4 | I4: =INDEX(Engagement!C:C,MATCH(Master_Data!A4,Engagement!A:A,0)) -> 2 | J4: =INDEX(Engagement!D:D,MATCH(Master_Data!A4,Engagement!A:A,0)) -> 1 | K4: =INDEX(Engagement!E:E,MATCH(Master_Data!A4,Engagement!A:A,0)) -> 3 | L4: =INDEX(Outcomes!B:B,MATCH(Master_Data!A4,Engagement!A:A,0)) -> Yes | M4: =INDEX(Outcomes!C:C,MATCH(Master_Data!A4,Engagement!A:A,0)) -> Employed | N4: =INDEX(Outcomes!D:D,MATCH(Master_Data!A4,Engagement!A:A,0)) -> Part-Time | O4: =INDEX(Outcomes!E:E,MATCH(Master_Data!A4,Engagement!A:A,0)) -> Technology | P4: =INDEX(Outcomes!F:F,MATCH(Master_Data!A4,Engagement!A:A,0)) -> 42873 | Q4: =INDEX(Outcomes!G:G,MATCH(Master_Data!A4,Engagement!A:A,0)) -> 4 | R4: =H4+I4+J4+K4 -> 10 | S4: =IF(M4="Employed","Positive Outcome", IF(M4="Continuing Education","Further Study", "Seeking")) -> Positive Outcome | T4: =IF(P4=0,"No Salary", IF(P4<50000,"Below 50K", IF(P4<=75000,"Between 50K and 75K", "Above 75K"))) -> Below 50K
A5: S004 | B5: =INDEX(Students!B:B,MATCH(Master_Data!A5,Students!A:A,0)) -> Alex Garcia | C5: =INDEX(Students!C:C,MATCH(Master_Data!A5,Students!A:A,0)) -> Data Science | D5: =INDEX(Students!D:D,MATCH(Master_Data!A5,Students!A:A,0)) -> Undergraduate | E5: =INDEX(Students!E:E,MATCH(Master_Data!A5,Students!A:A,0)) -> 2026 | F5: =INDEX(Students!F:F,MATCH(Master_Data!A5,Students!A:A,0)) -> 3.95 | G5: =INDEX(Students!G:G,MATCH(Master_Data!A5,Students!A:A,0)) -> Yes | H5: =INDEX(Engagement!B:B,MATCH(Master_Data!A5,Engagement!A:A,0)) -> 3 | I5: =INDEX(Engagement!C:C,MATCH(Master_Data!A5,Engagement!A:A,0)) -> 1 | J5: =INDEX(Engagement!D:D,MATCH(Master_Data!A5,Engagement!A:A,0)) -> 2 | K5: =INDEX(Engagement!E:E,MATCH(Master_Data!A5,Engagement!A:A,0)) -> 1 | L5: =INDEX(Outcomes!B:B,MATCH(Master_Data!A5,Engagement!A:A,0)) -> No | M5: =INDEX(Outcomes!C:C,MATCH(Master_Data!A5,Engagement!A:A,0)) -> Employed | N5: =INDEX(Outcomes!D:D,MATCH(Master_Data!A5,Engagement!A:A,0)) -> Full-Time | O5: =INDEX(Outcomes!E:E,MATCH(Master_Data!A5,Engagement!A:A,0)) -> Education | P5: =INDEX(Outcomes!F:F,MATCH(Master_Data!A5,Engagement!A:A,0)) -> 53883 | Q5: =INDEX(Outcomes!G:G,MATCH(Master_Data!A5,Engagement!A:A,0)) -> 3 | R5: =H5+I5+J5+K5 -> 7 | S5: =IF(M5="Employed","Positive Outcome", IF(M5="Continuing Education","Further Study", "Seeking")) -> Positive Outcome | T5: =IF(P5=0,"No Salary", IF(P5<50000,"Below 50K", IF(P5<=75000,"Between 50K and 75K", "Above 75K"))) -> Between 50K and 75K
A6: S005 | B6: =INDEX(Students!B:B,MATCH(Master_Data!A6,Students!A:A,0)) -> Taylor Martin | C6: =INDEX(Students!C:C,MATCH(Master_Data!A6,Students!A:A,0)) -> Business Analytics | D6: =INDEX(Students!D:D,MATCH(Master_Data!A6,Students!A:A,0)) -> Graduate | E6: =INDEX(Students!E:E,MATCH(Master_Data!A6,Students!A:A,0)) -> 2026 | F6: =INDEX(Students!F:F,MATCH(Master_Data!A6,Students!A:A,0)) -> 3.77 | G6: =INDEX(Students!G:G,MATCH(Master_Data!A6,Students!A:A,0)) -> No | H6: =INDEX(Engagement!B:B,MATCH(Master_Data!A6,Engagement!A:A,0)) -> 2 | I6: =INDEX(Engagement!C:C,MATCH(Master_Data!A6,Engagement!A:A,0)) -> 3 | J6: =INDEX(Engagement!D:D,MATCH(Master_Data!A6,Engagement!A:A,0)) -> 1 | K6: =INDEX(Engagement!E:E,MATCH(Master_Data!A6,Engagement!A:A,0)) -> 3 | L6: =INDEX(Outcomes!B:B,MATCH(Master_Data!A6,Engagement!A:A,0)) -> Yes | M6: =INDEX(Outcomes!C:C,MATCH(Master_Data!A6,Engagement!A:A,0)) -> Employed | N6: =INDEX(Outcomes!D:D,MATCH(Master_Data!A6,Engagement!A:A,0)) -> Full-Time | O6: =INDEX(Outcomes!E:E,MATCH(Master_Data!A6,Engagement!A:A,0)) -> Healthcare | P6: =INDEX(Outcomes!F:F,MATCH(Master_Data!A6,Engagement!A:A,0)) -> 64304 | Q6: =INDEX(Outcomes!G:G,MATCH(Master_Data!A6,Engagement!A:A,0)) -> 4 | R6: =H6+I6+J6+K6 -> 9 | S6: =IF(M6="Employed","Positive Outcome", IF(M6="Continuing Education","Further Study", "Seeking")) -> Positive Outcome | T6: =IF(P6=0,"No Salary", IF(P6<50000,"Below 50K", IF(P6<=75000,"Between 50K and 75K", "Above 75K"))) -> Between 50K and 75K
A7: S006 | B7: =INDEX(Students!B:B,MATCH(Master_Data!A7,Students!A:A,0)) -> Rowan Lee | C7: =INDEX(Students!C:C,MATCH(Master_Data!A7,Students!A:A,0)) -> Marketing | D7: =INDEX(Students!D:D,MATCH(Master_Data!A7,Students!A:A,0)) -> Undergraduate | E7: =INDEX(Students!E:E,MATCH(Master_Data!A7,Students!A:A,0)) -> 2026 | F7: =INDEX(Students!F:F,MATCH(Master_Data!A7,Students!A:A,0)) -> 3.8 | G7: =INDEX(Students!G:G,MATCH(Master_Data!A7,Students!A:A,0)) -> No | H7: =INDEX(Engagement!B:B,MATCH(Master_Data!A7,Engagement!A:A,0)) -> 5 | I7: =INDEX(Engagement!C:C,MATCH(Master_Data!A7,Engagement!A:A,0)) -> 0 | J7: =INDEX(Engagement!D:D,MATCH(Master_Data!A7,Engagement!A:A,0)) -> 0 | K7: =INDEX(Engagement!E:E,MATCH(Master_Data!A7,Engagement!A:A,0)) -> 1 | L7: =INDEX(Outcomes!B:B,MATCH(Master_Data!A7,Engagement!A:A,0)) -> No | M7: =INDEX(Outcomes!C:C,MATCH(Master_Data!A7,Engagement!A:A,0)) -> Seeking | N7: =INDEX(Outcomes!D:D,MATCH(Master_Data!A7,Engagement!A:A,0)) -> NA | O7: =INDEX(Outcomes!E:E,MATCH(Master_Data!A7,Engagement!A:A,0)) -> NA | P7: =INDEX(Outcomes!F:F,MATCH(Master_Data!A7,Engagement!A:A,0)) -> 0 | Q7: =INDEX(Outcomes!G:G,MATCH(Master_Data!A7,Engagement!A:A,0)) -> 0 | R7: =H7+I7+J7+K7 -> 6 | S7: =IF(M7="Employed","Positive Outcome", IF(M7="Continuing Education","Further Study", "Seeking")) -> Seeking | T7: =IF(P7=0,"No Salary", IF(P7<50000,"Below 50K", IF(P7<=75000,"Between 50K and 75K", "Above 75K"))) -> No Salary
A8: S007 | B8: =INDEX(Students!B:B,MATCH(Master_Data!A8,Students!A:A,0)) -> Parker Walker | C8: =INDEX(Students!C:C,MATCH(Master_Data!A8,Students!A:A,0)) -> Business Analytics | D8: =INDEX(Students!D:D,MATCH(Master_Data!A8,Students!A:A,0)) -> Undergraduate | E8: =INDEX(Students!E:E,MATCH(Master_Data!A8,Students!A:A,0)) -> 2027 | F8: =INDEX(Students!F:F,MATCH(Master_Data!A8,Students!A:A,0)) -> 3.73 | G8: =INDEX(Students!G:G,MATCH(Master_Data!A8,Students!A:A,0)) -> No | H8: =INDEX(Engagement!B:B,MATCH(Master_Data!A8,Engagement!A:A,0)) -> 4 | I8: =INDEX(Engagement!C:C,MATCH(Master_Data!A8,Engagement!A:A,0)) -> 1 | J8: =INDEX(Engagement!D:D,MATCH(Master_Data!A8,Engagement!A:A,0)) -> 3 | K8: =INDEX(Engagement!E:E,MATCH(Master_Data!A8,Engagement!A:A,0)) -> 1 | L8: =INDEX(Outcomes!B:B,MATCH(Master_Data!A8,Engagement!A:A,0)) -> No | M8: =INDEX(Outcomes!C:C,MATCH(Master_Data!A8,Engagement!A:A,0)) -> Seeking | N8: =INDEX(Outcomes!D:D,MATCH(Master_Data!A8,Engagement!A:A,0)) -> NA | O8: =INDEX(Outcomes!E:E,MATCH(Master_Data!A8,Engagement!A:A,0)) -> NA | P8: =INDEX(Outcomes!F:F,MATCH(Master_Data!A8,Engagement!A:A,0)) -> 0 | Q8: =INDEX(Outcomes!G:G,MATCH(Master_Data!A8,Engagement!A:A,0)) -> 0 | R8: =H8+I8+J8+K8 -> 9 | S8: =IF(M8="Employed","Positive Outcome", IF(M8="Continuing Education","Further Study", "Seeking")) -> Seeking | T8: =IF(P8=0,"No Salary", IF(P8<50000,"Below 50K", IF(P8<=75000,"Between 50K and 75K", "Above 75K"))) -> No Salary
A9: S008 | B9: =INDEX(Students!B:B,MATCH(Master_Data!A9,Students!A:A,0)) -> Cameron Lee | C9: =INDEX(Students!C:C,MATCH(Master_Data!A9,Students!A:A,0)) -> Computer Science | D9: =INDEX(Students!D:D,MATCH(Master_Data!A9,Students!A:A,0)) -> Graduate | E9: =INDEX(Students!E:E,MATCH(Master_Data!A9,Students!A:A,0)) -> 2027 | F9: =INDEX(Students!F:F,MATCH(Master_Data!A9,Students!A:A,0)) -> 3 | G9: =INDEX(Students!G:G,MATCH(Master_Data!A9,Students!A:A,0)) -> No | H9: =INDEX(Engagement!B:B,MATCH(Master_Data!A9,Engagement!A:A,0)) -> 3 | I9: =INDEX(Engagement!C:C,MATCH(Master_Data!A9,Engagement!A:A,0)) -> 1 | J9: =INDEX(Engagement!D:D,MATCH(Master_Data!A9,Engagement!A:A,0)) -> 3 | K9: =INDEX(Engagement!E:E,MATCH(Master_Data!A9,Engagement!A:A,0)) -> 3 | L9: =INDEX(Outcomes!B:B,MATCH(Master_Data!A9,Engagement!A:A,0)) -> No | M9: =INDEX(Outcomes!C:C,MATCH(Master_Data!A9,Engagement!A:A,0)) -> Employed | N9: =INDEX(Outcomes!D:D,MATCH(Master_Data!A9,Engagement!A:A,0)) -> Full-Time | O9: =INDEX(Outcomes!E:E,MATCH(Master_Data!A9,Engagement!A:A,0)) -> Marketing | P9: =INDEX(Outcomes!F:F,MATCH(Master_Data!A9,Engagement!A:A,0)) -> 53353 | Q9: =INDEX(Outcomes!G:G,MATCH(Master_Data!A9,Engagement!A:A,0)) -> 2 | R9: =H9+I9+J9+K9 -> 10 | S9: =IF(M9="Employed","Positive Outcome", IF(M9="Continuing Education","Further Study", "Seeking")) -> Positive Outcome | T9: =IF(P9=0,"No Salary", IF(P9<50000,"Below 50K", IF(P9<=75000,"Between 50K and 75K", "Above 75K"))) -> Between 50K and 75K
A10: S009 | B10: =INDEX(Students!B:B,MATCH(Master_Data!A10,Students!A:A,0)) -> Drew Brown | C10: =INDEX(Students!C:C,MATCH(Master_Data!A10,Students!A:A,0)) -> Data Science | D10: =INDEX(Students!D:D,MATCH(Master_Data!A10,Students!A:A,0)) -> Undergraduate | E10: =INDEX(Students!E:E,MATCH(Master_Data!A10,Students!A:A,0)) -> 2027 | F10: =INDEX(Students!F:F,MATCH(Master_Data!A10,Students!A:A,0)) -> 3 | G10: =INDEX(Students!G:G,MATCH(Master_Data!A10,Students!A:A,0)) -> No | H10: =INDEX(Engagement!B:B,MATCH(Master_Data!A10,Engagement!A:A,0)) -> 4 | I10: =INDEX(Engagement!C:C,MATCH(Master_Data!A10,Engagement!A:A,0)) -> 1 | J10: =INDEX(Engagement!D:D,MATCH(Master_Data!A10,Engagement!A:A,0)) -> 1 | K10: =INDEX(Engagement!E:E,MATCH(Master_Data!A10,Engagement!A:A,0)) -> 1 | L10: =INDEX(Outcomes!B:B,MATCH(Master_Data!A10,Engagement!A:A,0)) -> Yes | M10: =INDEX(Outcomes!C:C,MATCH(Master_Data!A10,Engagement!A:A,0)) -> Employed | N10: =INDEX(Outcomes!D:D,MATCH(Master_Data!A10,Engagement!A:A,0)) -> Internship | O10: =INDEX(Outcomes!E:E,MATCH(Master_Data!A10,Engagement!A:A,0)) -> Technology | P10: =INDEX(Outcomes!F:F,MATCH(Master_Data!A10,Engagement!A:A,0)) -> 37985 | Q10: =INDEX(Outcomes!G:G,MATCH(Master_Data!A10,Engagement!A:A,0)) -> 5 | R10: =H10+I10+J10+K10 -> 7 | S10: =IF(M10="Employed","Positive Outcome", IF(M10="Continuing Education","Further Study", "Seeking")) -> Positive Outcome | T10: =IF(P10=0,"No Salary", IF(P10<50000,"Below 50K", IF(P10<=75000,"Between 50K and 75K", "Above 75K"))) -> Below 50K
A11: S010 | B11: =INDEX(Students!B:B,MATCH(Master_Data!A11,Students!A:A,0)) -> Rowan Davis | C11: =INDEX(Students!C:C,MATCH(Master_Data!A11,Students!A:A,0)) -> Data Science | D11: =INDEX(Students!D:D,MATCH(Master_Data!A11,Students!A:A,0)) -> Graduate | E11: =INDEX(Students!E:E,MATCH(Master_Data!A11,Students!A:A,0)) -> 2027 | F11: =INDEX(Students!F:F,MATCH(Master_Data!A11,Students!A:A,0)) -> 3.07 | G11: =INDEX(Students!G:G,MATCH(Master_Data!A11,Students!A:A,0)) -> Yes | H11: =INDEX(Engagement!B:B,MATCH(Master_Data!A11,Engagement!A:A,0)) -> 3 | I11: =INDEX(Engagement!C:C,MATCH(Master_Data!A11,Engagement!A:A,0)) -> 1 | J11: =INDEX(Engagement!D:D,MATCH(Master_Data!A11,Engagement!A:A,0)) -> 2 | K11: =INDEX(Engagement!E:E,MATCH(Master_Data!A11,Engagement!A:A,0)) -> 2 | L11: =INDEX(Outcomes!B:B,MATCH(Master_Data!A11,Engagement!A:A,0)) -> Yes | M11: =INDEX(Outcomes!C:C,MATCH(Master_Data!A11,Engagement!A:A,0)) -> Employed | N11: =INDEX(Outcomes!D:D,MATCH(Master_Data!A11,Engagement!A:A,0)) -> Internship | O11: =INDEX(Outcomes!E:E,MATCH(Master_Data!A11,Engagement!A:A,0)) -> Technology | P11: =INDEX(Outcomes!F:F,MATCH(Master_Data!A11,Engagement!A:A,0)) -> 35622 | Q11: =INDEX(Outcomes!G:G,MATCH(Master_Data!A11,Engagement!A:A,0)) -> 5 | R11: =H11+I11+J11+K11 -> 8 | S11: =IF(M11="Employed","Positive Outcome", IF(M11="Continuing Education","Further Study", "Seeking")) -> Positive Outcome | T11: =IF(P11=0,"No Salary", IF(P11<50000,"Below 50K", IF(P11<=75000,"Between 50K and 75K", "Above 75K"))) -> Below 50K
A12: S011 | B12: =INDEX(Students!B:B,MATCH(Master_Data!A12,Students!A:A,0)) -> Skyler Martin | C12: =INDEX(Students!C:C,MATCH(Master_Data!A12,Students!A:A,0)) -> Computer Science | D12: =INDEX(Students!D:D,MATCH(Master_Data!A12,Students!A:A,0)) -> Undergraduate | E12: =INDEX(Students!E:E,MATCH(Master_Data!A12,Students!A:A,0)) -> 2027 | F12: =INDEX(Students!F:F,MATCH(Master_Data!A12,Students!A:A,0)) -> 3.85 | G12: =INDEX(Students!G:G,MATCH(Master_Data!A12,Students!A:A,0)) -> Yes | H12: =INDEX(Engagement!B:B,MATCH(Master_Data!A12,Engagement!A:A,0)) -> 3 | I12: =INDEX(Engagement!C:C,MATCH(Master_Data!A12,Engagement!A:A,0)) -> 1 | J12: =INDEX(Engagement!D:D,MATCH(Master_Data!A12,Engagement!A:A,0)) -> 1 | K12: =INDEX(Engagement!E:E,MATCH(Master_Data!A12,Engagement!A:A,0)) -> 1 | L12: =INDEX(Outcomes!B:B,MATCH(Master_Data!A12,Engagement!A:A,0)) -> Yes | M12: =INDEX(Outcomes!C:C,MATCH(Master_Data!A12,Engagement!A:A,0)) -> Employed | N12: =INDEX(Outcomes!D:D,MATCH(Master_Data!A12,Engagement!A:A,0)) -> Full-Time | O12: =INDEX(Outcomes!E:E,MATCH(Master_Data!A12,Engagement!A:A,0)) -> Marketing | P12: =INDEX(Outcomes!F:F,MATCH(Master_Data!A12,Engagement!A:A,0)) -> 58812 | Q12: =INDEX(Outcomes!G:G,MATCH(Master_Data!A12,Engagement!A:A,0)) -> 6 | R12: =H12+I12+J12+K12 -> 6 | S12: =IF(M12="Employed","Positive Outcome", IF(M12="Continuing Education","Further Study", "Seeking")) -> Positive Outcome | T12: =IF(P12=0,"No Salary", IF(P12<50000,"Below 50K", IF(P12<=75000,"Between 50K and 75K", "Above 75K"))) -> Between 50K and 75K
A13: S012 | B13: =INDEX(Students!B:B,MATCH(Master_Data!A13,Students!A:A,0)) -> Emerson Martin | C13: =INDEX(Students!C:C,MATCH(Master_Data!A13,Students!A:A,0)) -> Marketing | D13: =INDEX(Students!D:D,MATCH(Master_Data!A13,Students!A:A,0)) -> Graduate | E13: =INDEX(Students!E:E,MATCH(Master_Data!A13,Students!A:A,0)) -> 2026 | F13: =INDEX(Students!F:F,MATCH(Master_Data!A13,Students!A:A,0)) -> 2.97 | G13: =INDEX(Students!G:G,MATCH(Master_Data!A13,Students!A:A,0)) -> No | H13: =INDEX(Engagement!B:B,MATCH(Master_Data!A13,Engagement!A:A,0)) -> 4 | I13: =INDEX(Engagement!C:C,MATCH(Master_Data!A13,Engagement!A:A,0)) -> 1 | J13: =INDEX(Engagement!D:D,MATCH(Master_Data!A13,Engagement!A:A,0)) -> 0 | K13: =INDEX(Engagement!E:E,MATCH(Master_Data!A13,Engagement!A:A,0)) -> 2 | L13: =INDEX(Outcomes!B:B,MATCH(Master_Data!A13,Engagement!A:A,0)) -> Yes | M13: =INDEX(Outcomes!C:C,MATCH(Master_Data!A13,Engagement!A:A,0)) -> Seeking | N13: =INDEX(Outcomes!D:D,MATCH(Master_Data!A13,Engagement!A:A,0)) -> NA | O13: =INDEX(Outcomes!E:E,MATCH(Master_Data!A13,Engagement!A:A,0)) -> NA | P13: =INDEX(Outcomes!F:F,MATCH(Master_Data!A13,Engagement!A:A,0)) -> 0 | Q13: =INDEX(Outcomes!G:G,MATCH(Master_Data!A13,Engagement!A:A,0)) -> 0 | R13: =H13+I13+J13+K13 -> 7 | S13: =IF(M13="Employed","Positive Outcome", IF(M13="Continuing Education","Further Study", "Seeking")) -> Seeking | T13: =IF(P13=0,"No Salary", IF(P13<50000,"Below 50K", IF(P13<=75000,"Between 50K and 75K", "Above 75K"))) -> No Salary
... A121: S120 | B121: =INDEX(Students!B:B,MATCH(Master_Data!A121,Students!A:A,0)) -> Avery Hall | C121: =INDEX(Students!C:C,MATCH(Master_Data!A121,Students!A:A,0)) -> Economics | D121: =INDEX(Students!D:D,MATCH(Master_Data!A121,Students!A:A,0)) -> Graduate | E121: =INDEX(Students!E:E,MATCH(Master_Data!A121,Students!A:A,0)) -> 2027 | F121: =INDEX(Students!F:F,MATCH(Master_Data!A121,Students!A:A,0)) -> 3.13 | G121: =INDEX(Students!G:G,MATCH(Master_Data!A121,Students!A:A,0)) -> No | H121: =INDEX(Engagement!B:B,MATCH(Master_Data!A121,Engagement!A:A,0)) -> 4 | I121: =INDEX(Engagement!C:C,MATCH(Master_Data!A121,Engagement!A:A,0)) -> 3 | J121: =INDEX(Engagement!D:D,MATCH(Master_Data!A121,Engagement!A:A,0)) -> 0 | K121: =INDEX(Engagement!E:E,MATCH(Master_Data!A121,Engagement!A:A,0)) -> 1 | L121: =INDEX(Outcomes!B:B,MATCH(Master_Data!A121,Engagement!A:A,0)) -> Yes | M121: =INDEX(Outcomes!C:C,MATCH(Master_Data!A121,Engagement!A:A,0)) -> Employed | N121: =INDEX(Outcomes!D:D,MATCH(Master_Data!A121,Engagement!A:A,0)) -> Full-Time | O121: =INDEX(Outcomes!E:E,MATCH(Master_Data!A121,Engagement!A:A,0)) -> Marketing | P121: =INDEX(Outcomes!F:F,MATCH(Master_Data!A121,Engagement!A:A,0)) -> 61332 | Q121: =INDEX(Outcomes!G:G,MATCH(Master_Data!A121,Engagement!A:A,0)) -> 2 | R121: =H121+I121+J121+K121 -> 8 | S121: =IF(M121="Employed","Positive Outcome", IF(M121="Continuing Education","Further Study", "Seeking")) -> Positive Outcome | T121: =IF(P121=0,"No Salary", IF(P121<50000,"Below 50K", IF(P121<=75000,"Between 50K and 75K", "Above 75K"))) -> Between 50K and 75K

Sheet Summary_Analysis
A1: Summary Analysis
A3: KPI | B3: Value | E3: Row Labels | F3: Total Students | G3: % of Students
A4: Total Students | B4: =COUNTA(Master_Data!A2:A121) -> 120 | E4: Continuing Education | F4: 5 | G4: 0.070422535
A5: % Employed | B5: =COUNTIF(Master_Data!$M$2:$M$121,"Employed")/COUNTA(Master_Data!$A$2:$A$121) -> 0.675 | E5: Employed | F5: 43 | G5: 0.6056338
A6: % with Internship | B6: =COUNTIF(Master_Data!$L$2:$L$121,"Yes")/COUNTA(Master_Data!$A$2:$A$121) -> 0.725 | E6: Seeking | F6: 23 | G6: 0.32394366
A7: Average Salary | B7: =AVERAGEIF(Master_Data!P:P,">0") -> 58128.654 | E7: Grand Total | F7: 71 | G7: 1 | I7: Majors | J7: Student Count | K7: % of Students
A8: Average Engagement | B8: =AVERAGE(Master_Data!$R$2:$R$121) -> 7.9416667 | E8: Employment Status | I8: Consulting | J8: 10 | K8: 0.14084507
I9: Education | J9: 2 | K9: 0.028169014
I10: Finance | J10: 11 | K10: 0.15492958
I11: Healthcare | J11: 4 | K11: 0.056338028
I12: Marketing | J12: 5 | K12: 0.070422535
I13: NA | J13: 28 | K13: 0.3943662
A14: Student Count | B14: Emplyment Status | I14: Retail | J14: 4 | K14: 0.056338028
A15: Majors | B15: Continuing Education | C15: Employed | D15: Seeking | E15: Grand Total | I15: Technology | J15: 7 | K15: 0.098591549
A16: Business Analytics | B16: 1 | C16: 15 | D16: 4 | E16: 20 | I16: Grand Total | J16: 71 | K16: 1
A17: Economics | B17: 3 | C17: 10 | D17: 4 | E17: 17 | I17: Industry Distribution
A18: Finance | C18: 10 | D18: 6 | E18: 16
A19: Marketing | B19: 1 | C19: 8 | D19: 9 | E19: 18
A20: Grand Total | B20: 5 | C20: 43 | D20: 23 | E20: 71
H21: Student Count | I21: Outcome
H22: Total CCC events/sessions | I22: Further Study | J22: Positive Outcome | K22: Seeking | L22: Grand Total
A23: Employment Status by Majors | H23: 3 | J23: 2 | K23: 2 | L23: 4
H24: 4 | J24: 1 | L24: 1
H25: 5 | J25: 1 | K25: 4 | L25: 5
B26: Majors | C26: Average of Salary | H26: 6 | I26: 1 | J26: 6 | K26: 4 | L26: 11
B27: Business Analytics | C27: 45744.9 | H27: 7 | I27: 1 | J27: 7 | K27: 7 | L27: 15
B28: Economics | C28: 34228.176 | H28: 8 | I28: 3 | J28: 7 | K28: 2 | L28: 12
B29: Finance | C29: 33600.5 | H29: 9 | J29: 5 | K29: 4 | L29: 9
B30: Marketing | C30: 25355.667 | H30: 10 | J30: 3 | L30: 3
B31: Grand Total | C31: 35081.507 | H31: 11 | J31: 8 | L31: 8
H32: 12 | J32: 1 | L32: 1
H33: 13 | J33: 1 | L33: 1
B34: Avg Salary by Major | H34: 14 | J34: 1 | L34: 1
H35: Grand Total | I35: 5 | J35: 43 | K35: 23 | L35: 71
H36: Engagemnet by Employment Outcome

Sheet Dashboard
A1: Student Career Outcomes & Engagement Dashboard
A3: Total Students | D3: % Employed | G3: % with Internship | J3: Average Salary | M3: Average Engagement
A5: =COUNTA(Master_Data!A2:A121) -> 120 | D5: 0.675 | G5: 0.725 | J5: 58128.654 | M5: 7.9416667
M9: Emplyment vs Major
C10: Industry Distribution of Employed Students
C12: Consulting | D12: 20
C13: Education | D13: 5
C14: Finance | D14: 14
C15: Healthcare | D15: 6
C16: Marketing | D16: 10
C17: NA | D17: 39
C18: Retail | D18: 5
C19: Technology | D19: 21
C31: No. of CCC events attended vs Employment Status | M31: Employment Status
